<?xml version="1.0" ?>
<!-- =================================================================================== -->
<!-- |    This document was autogenerated by xacro from src/description/urdf/sentry.urdf.xacro | -->
<!-- |    EDITING THIS FILE BY HAND IS NOT RECOMMENDED                                 | -->
<!-- =================================================================================== -->
<robot name="my_robot">
  <!-- 圆形底盘 -->
  <link name="base_link">
    <visual>
      <geometry>
        <cylinder length="0.01" radius="0.2"/>
      </geometry>
      <material name="blue">
        <color rgba="0 0 0.8 1"/>
      </material>
    </visual>
    <collision>
      <geometry>
        <cylinder length="0.01" radius="0.2"/>
      </geometry>
    </collision>
  </link>
  <link name="front_left_link">
    <visual>
      <geometry>
        <cylinder length="0.03" radius="0.05"/>
      </geometry>
      <origin rpy="0 1.57075 0" xyz="-0.14142135623730953 0.14142135623730953 0"/>
      <material name="black">
        <color rgba="0 0 0 1"/>
      </material>
    </visual>
    <collision>
      <geometry>
        <cylinder length="0.03" radius="0.05"/>
      </geometry>
      <origin rpy="0 1.57075 0" xyz="-0.14142135623730953 0.14142135623730953 0"/>
    </collision>
  </link>
  <joint name="front_left_joint" type="continuous">
    <parent link="base_link"/>
    <child link="front_left_link"/>
    <axis xyz="0 0 1"/>
    <origin xyz="-0.14142135623730953 0.14142135623730953 0"/>
  </joint>
  <link name="front_right_link">
    <visual>
      <geometry>
        <cylinder length="0.03" radius="0.05"/>
      </geometry>
      <origin rpy="0 1.57075 0" xyz="0.14142135623730953 0.14142135623730953 0"/>
      <material name="black">
        <color rgba="0 0 0 1"/>
      </material>
    </visual>
    <collision>
      <geometry>
        <cylinder length="0.03" radius="0.05"/>
      </geometry>
      <origin rpy="0 1.57075 0" xyz="0.14142135623730953 0.14142135623730953 0"/>
    </collision>
  </link>
  <joint name="front_right_joint" type="continuous">
    <parent link="base_link"/>
    <child link="front_right_link"/>
    <axis xyz="0 0 1"/>
    <origin xyz="0.14142135623730953 0.14142135623730953 0"/>
  </joint>
  <link name="rear_left_link">
    <visual>
      <geometry>
        <cylinder length="0.03" radius="0.05"/>
      </geometry>
      <origin rpy="0 1.57075 0" xyz="-0.14142135623730953 -0.14142135623730953 0"/>
      <material name="black">
        <color rgba="0 0 0 1"/>
      </material>
    </visual>
    <collision>
      <geometry>
        <cylinder length="0.03" radius="0.05"/>
      </geometry>
      <origin rpy="0 1.57075 0" xyz="-0.14142135623730953 -0.14142135623730953 0"/>
    </collision>
  </link>
  <joint name="rear_left_joint" type="continuous">
    <parent link="base_link"/>
    <child link="rear_left_link"/>
    <axis xyz="0 0 1"/>
    <origin xyz="-0.14142135623730953 -0.14142135623730953 0"/>
  </joint>
  <link name="rear_right_link">
    <visual>
      <geometry>
        <cylinder length="0.03" radius="0.05"/>
      </geometry>
      <origin rpy="0 1.57075 0" xyz="0.14142135623730953 -0.14142135623730953 0"/>
      <material name="black">
        <color rgba="0 0 0 1"/>
      </material>
    </visual>
    <collision>
      <geometry>
        <cylinder length="0.03" radius="0.05"/>
      </geometry>
      <origin rpy="0 1.57075 0" xyz="0.14142135623730953 -0.14142135623730953 0"/>
    </collision>
  </link>
  <joint name="rear_right_joint" type="continuous">
    <parent link="base_link"/>
    <child link="rear_right_link"/>
    <axis xyz="0 0 1"/>
    <origin xyz="0.14142135623730953 -0.14142135623730953 0"/>
  </joint>
  <!-- 雷达和支架 -->
  <link name="cylinder_link">
    <visual>
      <geometry>
        <cylinder length="0.1" radius="0.02"/>
      </geometry>
      <material name="gray">
        <color rgba="0.5 0.5 0.5 1"/>
      </material>
    </visual>
    <collision>
      <geometry>
        <cylinder length="0.1" radius="0.02"/>
      </geometry>
    </collision>
  </link>
  <link name="lidar_link">
    <visual>
      <geometry>
        <cylinder length="0.05" radius="0.04"/>
      </geometry>
      <material name="red">
        <color rgba="0.8 0 0 1"/>
      </material>
    </visual>
    <collision>
      <geometry>
        <cylinder length="0.05" radius="0.04"/>
      </geometry>
    </collision>
  </link>
  <!-- 将支架连接到底盘 -->
  <joint name="cylinder_joint" type="fixed">
    <parent link="base_link"/>
    <child link="cylinder_link"/>
    <origin xyz="0 0 0.05"/>
  </joint>
  <!-- 将雷达连接到支架 -->
  <joint name="lidar_joint" type="fixed">
    <parent link="cylinder_link"/>
    <child link="lidar_link"/>
    <origin xyz="0 0 0.1"/>
  </joint>
</robot>
